Workbook

Sheet Товары
A1: Спецификация товаров по счетам-проформам UZ95-039-2026 … UZ95-045-2026 от 21.09.2026 и упаковочным листам к ним
A2: Отправитель: Permanent Establishment "Patentes Talgo SLU" in Uzbekistan (Ташкент). Получатель: PATENTES TALGO S.L.U (Las Matas, Madrid, Испания). Контракт EXP-72; DAP Madrid (Incoterms 2020); валюта — EUR; происхождение — Spain.
A3: Значения связаны формулами с листом «Исходные данные». Жёлтая заливка в столбце «Вес брутто» — расчётное значение: в упаковочном листе брутто указан на грузовое место целиком и распределён по позициям пропорционально весу нетто.
A4: № | B4: Счёт-проформа / PL № | C4: Артикул товара | D4: Наименование товара на русском языке | E4: Код ТН ВЭД | F4: Количество товара | G4: Единица измерения | H4: Стоимость товара, EUR | I4: Вес брутто, кг | J4: Вес нетто, кг | K4: Примечание аудитора (см. лист «Замечания»)
A5: 1 | B5: ='Исходные данные'!B5 -> UZ95-039-2026 | C5: ='Исходные данные'!H5 -> Z5069905A | D5: ='Исходные данные'!K5 -> КОМПЛЕКТ ВАЛОВ С НАБОРОМ КОЛЕС И ТЯГОВЫМ ДВИГАТЕЛЕМ | E5: ='Исходные данные'!M5 -> 8607191009 | F5: ='Исходные данные'!N5 -> 1 | G5: =IF('Исходные данные'!P5="UN","шт",'Исходные данные'!P5) -> шт | H5: ='Исходные данные'!S5 -> 1680 | I5: ='Исходные данные'!Z5 -> 4800 | J5: ='Исходные данные'!U5 -> 4500
A6: 2 | B6: ='Исходные данные'!B6 -> UZ95-039-2026 | C6: ='Исходные данные'!H6 -> Z5069905A | D6: ='Исходные данные'!K6 -> КОМПЛЕКТ ВАЛОВ С НАБОРОМ КОЛЕС И ТЯГОВЫМ ДВИГАТЕЛЕМ | E6: ='Исходные данные'!M6 -> 8607191009 | F6: ='Исходные данные'!N6 -> 1 | G6: =IF('Исходные данные'!P6="UN","шт",'Исходные данные'!P6) -> шт | H6: ='Исходные данные'!S6 -> 1680 | I6: ='Исходные данные'!Z6 -> 4800 | J6: ='Исходные данные'!U6 -> 4500
A7: 3 | B7: ='Исходные данные'!B7 -> UZ95-040-2026 | C7: ='Исходные данные'!H7 -> Z5069970A | D7: ='Исходные данные'!K7 -> КОМПЛЕКТ ВАЛОВ С НАБОРОМ КОЛЕС | E7: ='Исходные данные'!M7 -> 8607191009 | F7: ='Исходные данные'!N7 -> 3 | G7: =IF('Исходные данные'!P7="UN","шт",'Исходные данные'!P7) -> шт | H7: ='Исходные данные'!S7 -> 2280 | I7: ='Исходные данные'!Z7 -> 2305 | J7: ='Исходные данные'!U7 -> 2055
A8: 4 | B8: ='Исходные данные'!B8 -> UZ95-040-2026 | C8: ='Исходные данные'!H8 -> Z5069970A | D8: ='Исходные данные'!K8 -> КОМПЛЕКТ ВАЛОВ С НАБОРОМ КОЛЕС | E8: ='Исходные данные'!M8 -> 8607191009 | F8: ='Исходные данные'!N8 -> 3 | G8: =IF('Исходные данные'!P8="UN","шт",'Исходные данные'!P8) -> шт | H8: ='Исходные данные'!S8 -> 2280 | I8: ='Исходные данные'!Z8 -> 2305 | J8: ='Исходные данные'!U8 -> 2055
A9: 5 | B9: ='Исходные данные'!B9 -> UZ95-040-2026 | C9: ='Исходные данные'!H9 -> Z5069970A | D9: ='Исходные данные'!K9 -> КОМПЛЕКТ ВАЛОВ С НАБОРОМ КОЛЕС | E9: ='Исходные данные'!M9 -> 8607191009 | F9: ='Исходные данные'!N9 -> 3 | G9: =IF('Исходные данные'!P9="UN","шт",'Исходные данные'!P9) -> шт | H9: ='Исходные данные'!S9 -> 2280 | I9: ='Исходные данные'!Z9 -> 2305 | J9: ='Исходные данные'!U9 -> 2055
A10: 6 | B10: ='Исходные данные'!B10 -> UZ95-041-2026 | C10: ='Исходные данные'!H10 -> Z10001389 | D10: ='Исходные данные'!K10 -> МОДУЛЬ РЕГУЛИРОВКИ ВРАЩЕНИЯ 01 | E10: ='Исходные данные'!M10 -> 8542319010 | F10: ='Исходные данные'!N10 -> 7 | G10: =IF('Исходные данные'!P10="UN","шт",'Исходные данные'!P10) -> шт | H10: ='Исходные данные'!S10 -> 714 | I10: ='Исходные данные'!Z10 -> 21.85 | J10: ='Исходные данные'!U10 -> 12.6 | K10: Плата/модуль заявлены как интегральная схема (8542) — проверить (зам. 5)
A11: 7 | B11: ='Исходные данные'!B11 -> UZ95-041-2026 | C11: ='Исходные данные'!H11 -> Z10010402 | D11: ='Исходные данные'!K11 -> МОДУЛЬ ВВОДА ДАННЫХ SICAST350 | E11: ='Исходные данные'!M11 -> 8542319010 | F11: ='Исходные данные'!N11 -> 2 | G11: =IF('Исходные данные'!P11="UN","шт",'Исходные данные'!P11) -> шт | H11: ='Исходные данные'!S11 -> 942 | I11: ='Исходные данные'!Z11 -> 3.47 | J11: ='Исходные данные'!U11 -> 2 | K11: Плата/модуль заявлены как интегральная схема (8542) — проверить (зам. 5)
A12: 8 | B12: ='Исходные данные'!B12 -> UZ95-041-2026 | C12: ='Исходные данные'!H12 -> Z10010403 | D12: ='Исходные данные'!K12 -> ПЛАТА MVB(T) SICAS-T350 | E12: ='Исходные данные'!M12 -> 8542319010 | F12: ='Исходные данные'!N12 -> 1 | G12: =IF('Исходные данные'!P12="UN","шт",'Исходные данные'!P12) -> шт | H12: ='Исходные данные'!S12 -> 185 | I12: ='Исходные данные'!Z12 -> 0.35 | J12: ='Исходные данные'!U12 -> 0.2 | K12: Плата/модуль заявлены как интегральная схема (8542) — проверить (зам. 5)
A13: 9 | B13: ='Исходные данные'!B13 -> UZ95-041-2026 | C13: ='Исходные данные'!H13 -> Z10010440 | D13: ='Исходные данные'!K13 -> ПЛАТА ED1 SICAS-T350 | E13: ='Исходные данные'!M13 -> 8542319010 | F13: ='Исходные данные'!N13 -> 1 | G13: =IF('Исходные данные'!P13="UN","шт",'Исходные данные'!P13) -> шт | H13: ='Исходные данные'!S13 -> 471 | I13: ='Исходные данные'!Z13 -> 0.43 | J13: ='Исходные данные'!U13 -> 0.25 | K13: Плата/модуль заявлены как интегральная схема (8542) — проверить (зам. 5)
A14: 10 | B14: ='Исходные данные'!B14 -> UZ95-041-2026 | C14: ='Исходные данные'!H14 -> Z5035563A | D14: ='Исходные данные'!K14 -> ДАТЧИК ДЫМА | E14: ='Исходные данные'!M14 -> 8531109500 | F14: ='Исходные данные'!N14 -> 3 | G14: =IF('Исходные данные'!P14="UN","шт",'Исходные данные'!P14) -> шт | H14: ='Исходные данные'!S14 -> 720 | I14: ='Исходные данные'!Z14 -> 2.08 | J14: ='Исходные данные'!U14 -> 1.2
A15: 11 | B15: ='Исходные данные'!B15 -> UZ95-041-2026 | C15: ='Исходные данные'!H15 -> Z615677 | D15: ='Исходные данные'!K15 -> БЛОК СИСТЕМЫ АБС | E15: ='Исходные данные'!M15 -> 9032810000 | F15: ='Исходные данные'!N15 -> 6 | G15: =IF('Исходные данные'!P15="UN","шт",'Исходные данные'!P15) -> шт | H15: ='Исходные данные'!S15 -> 1872 | I15: ='Исходные данные'!Z15 -> 46.82 | J15: ='Исходные данные'!U15 -> 27 | K15: 9032 81 — гидравлические/пневматические приборы; товар электронный (зам. 4)
A16: 12 | B16: ='Исходные данные'!B16 -> UZ95-042-2026 | C16: ='Исходные данные'!H16 -> Z10063008 | D16: ='Исходные данные'!K16 -> ЦИФРОВОЙ ИНКЛИНОМЕТР | E16: ='Исходные данные'!M16 -> 9015900000 | F16: ='Исходные данные'!N16 -> 1 | G16: =IF('Исходные данные'!P16="UN","шт",'Исходные данные'!P16) -> шт | H16: ='Исходные данные'!S16 -> 350 | I16: ='Исходные данные'!Z16 -> 0.67 | J16: ='Исходные данные'!U16 -> 0.5 | K16: 9015 90 — части и принадлежности; товар — готовый прибор (зам. 7)
A17: 13 | B17: ='Исходные данные'!B17 -> UZ95-042-2026 | C17: ='Исходные данные'!H17 -> Z5001430A | D17: ='Исходные данные'!K17 -> КАЛИБРАТОР ДЛЯ ИЗМЕРЕНИЯ ПРОФИЛЯ КОЛЕСА | E17: ='Исходные данные'!M17 -> 9017300000 | F17: ='Исходные данные'!N17 -> 1 | G17: =IF('Исходные данные'!P17="UN","шт",'Исходные данные'!P17) -> шт | H17: ='Исходные данные'!S17 -> 1550 | I17: ='Исходные данные'!Z17 -> 6.66 | J17: ='Исходные данные'!U17 -> 5
A18: 14 | B18: ='Исходные данные'!B18 -> UZ95-042-2026 | C18: ='Исходные данные'!H18 -> Z594470 | D18: ='Исходные данные'!K18 -> КЛЕЩЕ (ПАТРОН) КАЛИБРОВОЧНЫЙ | E18: ='Исходные данные'!M18 -> 9015900000 | F18: ='Исходные данные'!N18 -> 1 | G18: =IF('Исходные данные'!P18="UN","шт",'Исходные данные'!P18) -> шт | H18: ='Исходные данные'!S18 -> 90 | I18: ='Исходные данные'!Z18 -> 2.67 | J18: ='Исходные данные'!U18 -> 2 | K18: Неясное слово «КЛЕЩЕ» (зам. 9); код 9015 90 — части и принадлежности (зам. 7)
A19: 15 | B19: ='Исходные данные'!B19 -> UZ95-043-2026 | C19: ='Исходные данные'!H19 -> Z10001801 | D19: ='Исходные данные'!K19 -> МОДУЛЬ ВВОДА/ВЫВОДА ДАННЫХ | E19: ='Исходные данные'!M19 -> 8542319010 | F19: ='Исходные данные'!N19 -> 1 | G19: =IF('Исходные данные'!P19="UN","шт",'Исходные данные'!P19) -> шт | H19: ='Исходные данные'!S19 -> 347 | I19: ='Исходные данные'!Z19 -> 0.98 | J19: ='Исходные данные'!U19 -> 0.8 | K19: Плата/модуль заявлены как интегральная схема (8542) — проверить (зам. 5)
A20: 16 | B20: ='Исходные данные'!B20 -> UZ95-043-2026 | C20: ='Исходные данные'!H20 -> Z10014704 | D20: ='Исходные данные'!K20 -> ЭЛЕКТРОНУМАТИЧЕСКИЙ МОДУЛЯТОР (ЭПМ) | E20: ='Исходные данные'!M20 -> 8607998000 | F20: ='Исходные данные'!N20 -> 1 | G20: =IF('Исходные данные'!P20="UN","шт",'Исходные данные'!P20) -> шт | H20: ='Исходные данные'!S20 -> 735.92 | I20: ='Исходные данные'!Z20 -> 2.94 | J20: ='Исходные данные'!U20 -> 2.4 | K20: Опечатка: верно «ЭЛЕКТРОПНЕВМАТИЧЕСКИЙ» — перенесено как в оригинале (зам. 8)
A21: 17 | B21: ='Исходные данные'!B21 -> UZ95-043-2026 | C21: ='Исходные данные'!H21 -> Z10014705 | D21: ='Исходные данные'!K21 -> ЕВРОТРОЛЬ (РЕГУЛ.ТОРМ.СИСТЕМЫ) | E21: ='Исходные данные'!M21 -> 8607219000 | F21: ='Исходные данные'!N21 -> 3 | G21: =IF('Исходные данные'!P21="UN","шт",'Исходные данные'!P21) -> шт | H21: ='Исходные данные'!S21 -> 2850 | I21: ='Исходные данные'!Z21 -> 95.63 | J21: ='Исходные данные'!U21 -> 78
A22: 18 | B22: ='Исходные данные'!B22 -> UZ95-043-2026 | C22: ='Исходные данные'!H22 -> Z10014712 | D22: ='Исходные данные'!K22 -> РЕЛЕ КЛАПАНА ДАВЛЕНИЯ | E22: ='Исходные данные'!M22 -> 8536490000 | F22: ='Исходные данные'!N22 -> 1 | G22: =IF('Исходные данные'!P22="UN","шт",'Исходные данные'!P22) -> шт | H22: ='Исходные данные'!S22 -> 841.71 | I22: ='Исходные данные'!Z22 -> 8.58 | J22: ='Исходные данные'!U22 -> 7
A23: 19 | B23: ='Исходные данные'!B23 -> UZ95-043-2026 | C23: ='Исходные данные'!H23 -> Z10016893 | D23: ='Исходные данные'!K23 -> ДИСТРИБЬЮТОР SW4 | E23: ='Исходные данные'!M23 -> 8607219000 | F23: ='Исходные данные'!N23 -> 2 | G23: =IF('Исходные данные'!P23="UN","шт",'Исходные данные'!P23) -> шт | H23: ='Исходные данные'!S23 -> 1181.3 | I23: ='Исходные данные'!Z23 -> 31.87 | J23: ='Исходные данные'!U23 -> 26
A24: 20 | B24: ='Исходные данные'!B24 -> UZ95-043-2026 | C24: ='Исходные данные'!H24 -> Z10030325 | D24: ='Исходные данные'!K24 -> ПЛАТА DPI 1 | E24: ='Исходные данные'!M24 -> 8542319010 | F24: ='Исходные данные'!N24 -> 2 | G24: =IF('Исходные данные'!P24="UN","шт",'Исходные данные'!P24) -> шт | H24: ='Исходные данные'!S24 -> 942 | I24: ='Исходные данные'!Z24 -> 0.49 | J24: ='Исходные данные'!U24 -> 0.4 | K24: Плата/модуль заявлены как интегральная схема (8542) — проверить (зам. 5)
A25: 21 | B25: ='Исходные данные'!B25 -> UZ95-043-2026 | C25: ='Исходные данные'!H25 -> Z10035917 | D25: ='Исходные данные'!K25 -> ПЛАТА ТЕМПЕРАТУРЫ (PT100) | E25: ='Исходные данные'!M25 -> 8531109500 | F25: ='Исходные данные'!N25 -> 1 | G25: =IF('Исходные данные'!P25="UN","шт",'Исходные данные'!P25) -> шт | H25: ='Исходные данные'!S25 -> 386.02 | I25: ='Исходные данные'!Z25 -> 0.25 | J25: ='Исходные данные'!U25 -> 0.2 | K25: 8531 10 — сигнализация; товар — плата/мультиплексор температуры (зам. 6)
A26: 22 | B26: ='Исходные данные'!B26 -> UZ95-043-2026 | C26: ='Исходные данные'!H26 -> Z10035979 | D26: ='Исходные данные'!K26 -> КОНТАКТОР 100A 4000V | E26: ='Исходные данные'!M26 -> 8536490000 | F26: ='Исходные данные'!N26 -> 1 | G26: =IF('Исходные данные'!P26="UN","шт",'Исходные данные'!P26) -> шт | H26: ='Исходные данные'!S26 -> 204 | I26: ='Исходные данные'!Z26 -> 8.58 | J26: ='Исходные данные'!U26 -> 7 | K26: 8536 — аппаратура до 1000 В; в описании 4000V (зам. 3)
A27: 23 | B27: ='Исходные данные'!B27 -> UZ95-043-2026 | C27: ='Исходные данные'!H27 -> Z10037362 | D27: ='Исходные данные'!K27 -> БЛОК ПИТАНИЯ CPCI TEAM | E27: ='Исходные данные'!M27 -> 8504409000 | F27: ='Исходные данные'!N27 -> 4 | G27: =IF('Исходные данные'!P27="UN","шт",'Исходные данные'!P27) -> шт | H27: ='Исходные данные'!S27 -> 1987 | I27: ='Исходные данные'!Z27 -> 3.92 | J27: ='Исходные данные'!U27 -> 3.2
A28: 24 | B28: ='Исходные данные'!B28 -> UZ95-043-2026 | C28: ='Исходные данные'!H28 -> Z10037794 | D28: ='Исходные данные'!K28 -> МОДУЛЬ 12 ВВОДА ДАННЫХ PT100 | E28: ='Исходные данные'!M28 -> 8542319010 | F28: ='Исходные данные'!N28 -> 1 | G28: =IF('Исходные данные'!P28="UN","шт",'Исходные данные'!P28) -> шт | H28: ='Исходные данные'!S28 -> 497.2 | I28: ='Исходные данные'!Z28 -> 0.49 | J28: ='Исходные данные'!U28 -> 0.4 | K28: Плата/модуль заявлены как интегральная схема (8542) — проверить (зам. 5)
A29: 25 | B29: ='Исходные данные'!B29 -> UZ95-043-2026 | C29: ='Исходные данные'!H29 -> Z10050907 | D29: ='Исходные данные'!K29 -> МОДУЛЬ 4 IGBTS | E29: ='Исходные данные'!M29 -> 8504408400 | F29: ='Исходные данные'!N29 -> 2 | G29: =IF('Исходные данные'!P29="UN","шт",'Исходные данные'!P29) -> шт | H29: ='Исходные данные'!S29 -> 2400 | I29: ='Исходные данные'!Z29 -> 76 | J29: ='Исходные данные'!U29 -> 62
A30: 26 | B30: ='Исходные данные'!B30 -> UZ95-043-2026 | C30: ='Исходные данные'!H30 -> Z10060936 | D30: ='Исходные данные'!K30 -> ЭЛЕКТРОКЛАПАН 21C | E30: ='Исходные данные'!M30 -> 8481807399 | F30: ='Исходные данные'!N30 -> 1 | G30: =IF('Исходные данные'!P30="UN","шт",'Исходные данные'!P30) -> шт | H30: ='Исходные данные'!S30 -> 845 | I30: ='Исходные данные'!Z30 -> 2.45 | J30: ='Исходные данные'!U30 -> 2
A31: 27 | B31: ='Исходные данные'!B31 -> UZ95-043-2026 | C31: ='Исходные данные'!H31 -> Z10062945 | D31: ='Исходные данные'!K31 -> ПЛАТА ИЗМЕРИТЕЛЬНАЯ | E31: ='Исходные данные'!M31 -> 8542319010 | F31: ='Исходные данные'!N31 -> 1 | G31: =IF('Исходные данные'!P31="UN","шт",'Исходные данные'!P31) -> шт | H31: ='Исходные данные'!S31 -> 350 | I31: ='Исходные данные'!Z31 -> 0.37 | J31: ='Исходные данные'!U31 -> 0.3 | K31: Плата/модуль заявлены как интегральная схема (8542) — проверить (зам. 5)
A32: 28 | B32: ='Исходные данные'!B32 -> UZ95-043-2026 | C32: ='Исходные данные'!H32 -> Z5039543A | D32: ='Исходные данные'!K32 -> ЦЕНТРАЛЬНАЯ ПАНЕЛЬ УПРАВЛЕНИЯ | E32: ='Исходные данные'!M32 -> 8537109900 | F32: ='Исходные данные'!N32 -> 1 | G32: =IF('Исходные данные'!P32="UN","шт",'Исходные данные'!P32) -> шт | H32: ='Исходные данные'!S32 -> 148.56 | I32: ='Исходные данные'!Z32 -> 2.45 | J32: ='Исходные данные'!U32 -> 2 | K32: Строка не включена в TOTAL FACTURA счёта 043 (зам. 1)
A33: 29 | B33: ='Исходные данные'!B33 -> UZ95-044-2026 | C33: ='Исходные данные'!H33 -> Z10010755 | D33: ='Исходные данные'!K33 -> АМОРТИЗАТОР 130,730,102,112 | E33: ='Исходные данные'!M33 -> 8607919000 | F33: ='Исходные данные'!N33 -> 19 | G33: =IF('Исходные данные'!P33="UN","шт",'Исходные данные'!P33) -> шт | H33: ='Исходные данные'!S33 -> 760 | I33: ='Исходные данные'!Z33 -> 242.41 | J33: ='Исходные данные'!U33 -> 228 | K33: Код 8607 91, а у однотипного «АМОРТИЗАТОР 130» — 8607 19 (зам. 2)
A34: 30 | B34: ='Исходные данные'!B34 -> UZ95-044-2026 | C34: ='Исходные данные'!H34 -> Z5040584A | D34: ='Исходные данные'!K34 -> АМОРТИЗАТОР 130 | E34: ='Исходные данные'!M34 -> 8607199000 | F34: ='Исходные данные'!N34 -> 10 | G34: =IF('Исходные данные'!P34="UN","шт",'Исходные данные'!P34) -> шт | H34: ='Исходные данные'!S34 -> 390 | I34: ='Исходные данные'!Z34 -> 127.59 | J34: ='Исходные данные'!U34 -> 120
A35: 31 | B35: ='Исходные данные'!B35 -> UZ95-045-2026 | C35: ='Исходные данные'!H35 -> Z5024835A | D35: ='Исходные данные'!K35 -> АМОРТИЗАТОР-ГАСИТЕЛЬ УГЛОВЫХ КОЛЕБАНИЙ | E35: ='Исходные данные'!M35 -> 8607199000 | F35: ='Исходные данные'!N35 -> 2 | G35: =IF('Исходные данные'!P35="UN","шт",'Исходные данные'!P35) -> шт | H35: ='Исходные данные'!S35 -> 167.54 | I35: ='Исходные данные'!Z35 -> 48.15 | J35: ='Исходные данные'!U35 -> 46
A36: 32 | B36: ='Исходные данные'!B36 -> UZ95-045-2026 | C36: ='Исходные данные'!H36 -> Z5024837A | D36: ='Исходные данные'!K36 -> АМОРТИЗАТОР ПОДВЕСНОЙ (ВТОРИЧНЫЙ) | E36: ='Исходные данные'!M36 -> 8607199000 | F36: ='Исходные данные'!N36 -> 2 | G36: =IF('Исходные данные'!P36="UN","шт",'Исходные данные'!P36) -> шт | H36: ='Исходные данные'!S36 -> 144 | I36: ='Исходные данные'!Z36 -> 33.49 | J36: ='Исходные данные'!U36 -> 32
A37: 33 | B37: ='Исходные данные'!B37 -> UZ95-045-2026 | C37: ='Исходные данные'!H37 -> Z5050054A | D37: ='Исходные данные'!K37 -> ПОПЕРЕЧНЫЙ АНТИВИБРАЦИОННЫЙ АМОРТИЗАТОР | E37: ='Исходные данные'!M37 -> 8607199000 | F37: ='Исходные данные'!N37 -> 1 | G37: =IF('Исходные данные'!P37="UN","шт",'Исходные данные'!P37) -> шт | H37: ='Исходные данные'!S37 -> 47 | I37: ='Исходные данные'!Z37 -> 21.98 | J37: ='Исходные данные'!U37 -> 21
A38: 34 | B38: ='Исходные данные'!B38 -> UZ95-045-2026 | C38: ='Исходные данные'!H38 -> Z5050055A | D38: ='Исходные данные'!K38 -> ПОПЕРЕЧНЫЙ АНТИВИБРАЦИОННЫЙ АМОРТИЗАТОР | E38: ='Исходные данные'!M38 -> 8607919000 | F38: ='Исходные данные'!N38 -> 1 | G38: =IF('Исходные данные'!P38="UN","шт",'Исходные данные'!P38) -> шт | H38: ='Исходные данные'!S38 -> 47 | I38: ='Исходные данные'!Z38 -> 24.07 | J38: ='Исходные данные'!U38 -> 23 | K38: Код 8607 91 при коде 8607 19 у позиций с тем же наименованием (Z5050054A/57A/58A) (зам. 2)
A39: 35 | B39: ='Исходные данные'!B39 -> UZ95-045-2026 | C39: ='Исходные данные'!H39 -> Z5050057A | D39: ='Исходные данные'!K39 -> ПОПЕРЕЧНЫЙ АНТИВИБРАЦИОННЫЙ АМОРТИЗАТОР | E39: ='Исходные данные'!M39 -> 8607199000 | F39: ='Исходные данные'!N39 -> 2 | G39: =IF('Исходные данные'!P39="UN","шт",'Исходные данные'!P39) -> шт | H39: ='Исходные данные'!S39 -> 178 | I39: ='Исходные данные'!Z39 -> 62.8 | J39: ='Исходные данные'!U39 -> 60
A40: 36 | B40: ='Исходные данные'!B40 -> UZ95-045-2026 | C40: ='Исходные данные'!H40 -> Z5050058A | D40: ='Исходные данные'!K40 -> ПОПЕРЕЧНЫЙ АНТИВИБРАЦИОННЫЙ АМОРТИЗАТОР | E40: ='Исходные данные'!M40 -> 8607199000 | F40: ='Исходные данные'!N40 -> 2 | G40: =IF('Исходные данные'!P40="UN","шт",'Исходные данные'!P40) -> шт | H40: ='Исходные данные'!S40 -> 178 | I40: ='Исходные данные'!Z40 -> 62.8 | J40: ='Исходные данные'!U40 -> 60
...

Sheet Исходные данные
A1: Исходные данные: построчный перенос со сканов счетов-проформ и упаковочных листов (PL) с проверками
A2: Синий шрифт — значения, перенесённые из документов (файл 8c38d916-supporting_4.pdf, стр. указаны в столбце C). Чёрный — формулы. Столбцы W–Z: распределение веса брутто места по позициям пропорционально весу нетто (округление до 0,01 кг; остаток округления относится на позицию с наибольшим весом нетто в месте).
A4: № | B4: Счёт-проформа / PL № | C4: Стр. PDF (счёт / PL) | D4: № паллеты (Bulto nr) по счёту | E4: Место по PL | F4: Габариты места (ДхШхВ), см | G4: Ключ места | H4: Артикул (счёт) | I4: Артикул (PL) | J4: Описание (исп.), счёт | K4: Наименование (рус.), счёт | L4: Наименование (рус.), PL | M4: Код ТН ВЭД (счёт) | N4: Кол-во (счёт) | O4: Кол-во (PL) | P4: Ед. изм. (счёт) | Q4: Упаковка | R4: Цена за ед., EUR | S4: Стоимость по счёту, EUR | T4: Вес нетто 1 шт., кг (PL) | U4: Вес нетто по PL, кг | V4: Вес брутто места по PL, кг | W4: Нетто места, кг | X4: Брутто: пропорц. доля (округл.), кг | Y4: Остаток округления на эту строку (1/0) | Z4: Вес брутто позиции, кг (расчётный) | AA4: Проверка: кол-во × цена = стоимость | AB4: Проверка: кол-во × вес 1 шт. = нетто | AC4: Проверка: артикул счёт = PL | AD4: Проверка: наименование счёт = PL | AE4: Проверка: кол-во счёт = PL
A5: 1 | B5: UZ95-039-2026 | C5: 1 / 2 | D5: 10 | E5: 1 | F5: 200x260x150 | G5: =B5&" | место "&E5 -> UZ95-039-2026 | место 1 | H5: Z5069905A | I5: Z5069905A | J5: EJE DE TRACCION COMPLETO REPARADO | K5: КОМПЛЕКТ ВАЛОВ С НАБОРОМ КОЛЕС И ТЯГОВЫМ ДВИГАТЕЛЕМ | L5: КОМПЛЕКТ ВАЛОВ С НАБОРОМ КОЛЕС И ТЯГОВЫМ ДВИГАТЕЛЕМ | M5: 8607191009 | N5: 1 | O5: 1 | P5: UN | Q5: PM | R5: 1680 | S5: 1680 | T5: 4500 | U5: 4500 | V5: 4800 | W5: =SUMIFS($U$5:$U$44,$G$5:$G$44,G5) -> 4500 | X5: =ROUND(V5*U5/W5,2) -> 4800 | Y5: =IF(AND(U5=_xlfn.MAXIFS($U$5:$U$44,$G$5:$G$44,G5),COUNTIFS($G$5:G5,G5,$U$5:U5,U5)=1),1,0) -> 1 | Z5: =ROUND(IF(Y5=1,V5-(SUMIFS($X$5:$X$44,$G$5:$G$44,G5)-X5),X5),2) -> 4800 | AA5: =IF(ABS(N5*R5-S5)<0.005,"OK","ОШИБКА") -> OK | AB5: =IF(ABS(O5*T5-U5)<0.0005,"OK","ОШИБКА") -> OK | AC5: =IF(H5=I5,"OK","ОШИБКА") -> OK | AD5: =IF(K5=L5,"OK","ОШИБКА") -> OK | AE5: =IF(N5=O5,"OK","ОШИБКА") -> OK
A6: 2 | B6: UZ95-039-2026 | C6: 1 / 2 | D6: 11 | E6: 2 | F6: 200x260x150 | G6: =B6&" | место "&E6 -> UZ95-039-2026 | место 2 | H6: Z5069905A | I6: Z5069905A | J6: EJE DE TRACCION COMPLETO REPARADO | K6: КОМПЛЕКТ ВАЛОВ С НАБОРОМ КОЛЕС И ТЯГОВЫМ ДВИГАТЕЛЕМ | L6: КОМПЛЕКТ ВАЛОВ С НАБОРОМ КОЛЕС И ТЯГОВЫМ ДВИГАТЕЛЕМ | M6: 8607191009 | N6: 1 | O6: 1 | P6: UN | Q6: PM | R6: 1680 | S6: 1680 | T6: 4500 | U6: 4500 | V6: 4800 | W6: =SUMIFS($U$5:$U$44,$G$5:$G$44,G6) -> 4500 | X6: =ROUND(V6*U6/W6,2) -> 4800 | Y6: =IF(AND(U6=_xlfn.MAXIFS($U$5:$U$44,$G$5:$G$44,G6),COUNTIFS($G$5:G6,G6,$U$5:U6,U6)=1),1,0) -> 1 | Z6: =ROUND(IF(Y6=1,V6-(SUMIFS($X$5:$X$44,$G$5:$G$44,G6)-X6),X6),2) -> 4800 | AA6: =IF(ABS(N6*R6-S6)<0.005,"OK","ОШИБКА") -> OK | AB6: =IF(ABS(O6*T6-U6)<0.0005,"OK","ОШИБКА") -> OK | AC6: =IF(H6=I6,"OK","ОШИБКА") -> OK | AD6: =IF(K6=L6,"OK","ОШИБКА") -> OK | AE6: =IF(N6=O6,"OK","ОШИБКА") -> OK
A7: 3 | B7: UZ95-040-2026 | C7: 3 / 4 | D7: 5 | E7: 1 | F7: 215x130x127 | G7: =B7&" | место "&E7 -> UZ95-040-2026 | место 1 | H7: Z5069970A | I7: Z5069970A | J7: EJE RODADURA COMPLETO REPARADO RODAL | K7: КОМПЛЕКТ ВАЛОВ С НАБОРОМ КОЛЕС | L7: КОМПЛЕКТ ВАЛОВ С НАБОРОМ КОЛЕС | M7: 8607191009 | N7: 3 | O7: 3 | P7: UN | Q7: PM | R7: 760 | S7: 2280 | T7: 685 | U7: 2055 | V7: 2305 | W7: =SUMIFS($U$5:$U$44,$G$5:$G$44,G7) -> 2055 | X7: =ROUND(V7*U7/W7,2) -> 2305 | Y7: =IF(AND(U7=_xlfn.MAXIFS($U$5:$U$44,$G$5:$G$44,G7),COUNTIFS($G$5:G7,G7,$U$5:U7,U7)=1),1,0) -> 1 | Z7: =ROUND(IF(Y7=1,V7-(SUMIFS($X$5:$X$44,$G$5:$G$44,G7)-X7),X7),2) -> 2305 | AA7: =IF(ABS(N7*R7-S7)<0.005,"OK","ОШИБКА") -> OK | AB7: =IF(ABS(O7*T7-U7)<0.0005,"OK","ОШИБКА") -> OK | AC7: =IF(H7=I7,"OK","ОШИБКА") -> OK | AD7: =IF(K7=L7,"OK","ОШИБКА") -> OK | AE7: =IF(N7=O7,"OK","ОШИБКА") -> OK
A8: 4 | B8: UZ95-040-2026 | C8: 3 / 4 | D8: 6 | E8: 2 | F8: 215x130x127 | G8: =B8&" | место "&E8 -> UZ95-040-2026 | место 2 | H8: Z5069970A | I8: Z5069970A | J8: EJE RODADURA COMPLETO REPARADO RODAL | K8: КОМПЛЕКТ ВАЛОВ С НАБОРОМ КОЛЕС | L8: КОМПЛЕКТ ВАЛОВ С НАБОРОМ КОЛЕС | M8: 8607191009 | N8: 3 | O8: 3 | P8: UN | Q8: PM | R8: 760 | S8: 2280 | T8: 685 | U8: 2055 | V8: 2305 | W8: =SUMIFS($U$5:$U$44,$G$5:$G$44,G8) -> 2055 | X8: =ROUND(V8*U8/W8,2) -> 2305 | Y8: =IF(AND(U8=_xlfn.MAXIFS($U$5:$U$44,$G$5:$G$44,G8),COUNTIFS($G$5:G8,G8,$U$5:U8,U8)=1),1,0) -> 1 | Z8: =ROUND(IF(Y8=1,V8-(SUMIFS($X$5:$X$44,$G$5:$G$44,G8)-X8),X8),2) -> 2305 | AA8: =IF(ABS(N8*R8-S8)<0.005,"OK","ОШИБКА") -> OK | AB8: =IF(ABS(O8*T8-U8)<0.0005,"OK","ОШИБКА") -> OK | AC8: =IF(H8=I8,"OK","ОШИБКА") -> OK | AD8: =IF(K8=L8,"OK","ОШИБКА") -> OK | AE8: =IF(N8=O8,"OK","ОШИБКА") -> OK
A9: 5 | B9: UZ95-040-2026 | C9: 3 / 4 | D9: 7 | E9: 3 | F9: 215x130x127 | G9: =B9&" | место "&E9 -> UZ95-040-2026 | место 3 | H9: Z5069970A | I9: Z5069970A | J9: EJE RODADURA COMPLETO REPARADO RODAL | K9: КОМПЛЕКТ ВАЛОВ С НАБОРОМ КОЛЕС | L9: КОМПЛЕКТ ВАЛОВ С НАБОРОМ КОЛЕС | M9: 8607191009 | N9: 3 | O9: 3 | P9: UN | Q9: PM | R9: 760 | S9: 2280 | T9: 685 | U9: 2055 | V9: 2305 | W9: =SUMIFS($U$5:$U$44,$G$5:$G$44,G9) -> 2055 | X9: =ROUND(V9*U9/W9,2) -> 2305 | Y9: =IF(AND(U9=_xlfn.MAXIFS($U$5:$U$44,$G$5:$G$44,G9),COUNTIFS($G$5:G9,G9,$U$5:U9,U9)=1),1,0) -> 1 | Z9: =ROUND(IF(Y9=1,V9-(SUMIFS($X$5:$X$44,$G$5:$G$44,G9)-X9),X9),2) -> 2305 | AA9: =IF(ABS(N9*R9-S9)<0.005,"OK","ОШИБКА") -> OK | AB9: =IF(ABS(O9*T9-U9)<0.0005,"OK","ОШИБКА") -> OK | AC9: =IF(H9=I9,"OK","ОШИБКА") -> OK | AD9: =IF(K9=L9,"OK","ОШИБКА") -> OK | AE9: =IF(N9=O9,"OK","ОШИБКА") -> OK
A10: 6 | B10: UZ95-041-2026 | C10: 5 / 6 | D10: 2 | E10: 1 | F10: 120x80x65 | G10: =B10&" | место "&E10 -> UZ95-041-2026 | место 1 | H10: Z10001389 | I10: Z10001389 | J10: MODULO SUPERVISION RODADURA 01 | K10: МОДУЛЬ РЕГУЛИРОВКИ ВРАЩЕНИЯ 01 | L10: МОДУЛЬ РЕГУЛИРОВКИ ВРАЩЕНИЯ 01 | M10: 8542319010 | N10: 7 | O10: 7 | P10: UN | Q10: PM | R10: 102 | S10: 714 | T10: 1.8 | U10: 12.6 | V10: 75 | W10: =SUMIFS($U$5:$U$44,$G$5:$G$44,G10) -> 43.25 | X10: =ROUND(V10*U10/W10,2) -> 21.85 | Y10: =IF(AND(U10=_xlfn.MAXIFS($U$5:$U$44,$G$5:$G$44,G10),COUNTIFS($G$5:G10,G10,$U$5:U10,U10)=1),1,0) -> 0 | Z10: =ROUND(IF(Y10=1,V10-(SUMIFS($X$5:$X$44,$G$5:$G$44,G10)-X10),X10),2) -> 21.85 | AA10: =IF(ABS(N10*R10-S10)<0.005,"OK","ОШИБКА") -> OK | AB10: =IF(ABS(O10*T10-U10)<0.0005,"OK","ОШИБКА") -> OK | AC10: =IF(H10=I10,"OK","ОШИБКА") -> OK | AD10: =IF(K10=L10,"OK","ОШИБКА") -> OK | AE10: =IF(N10=O10,"OK","ОШИБКА") -> OK
A11: 7 | B11: UZ95-041-2026 | C11: 5 / 6 | D11: 2 | E11: 1 | F11: 120x80x65 | G11: =B11&" | место "&E11 -> UZ95-041-2026 | место 1 | H11: Z10010402 | I11: Z10010402 | J11: MODULO F.A. Y DISPLAY SICAST350 REPARADO | K11: МОДУЛЬ ВВОДА ДАННЫХ SICAST350 | L11: МОДУЛЬ ВВОДА ДАННЫХ SICAST350 | M11: 8542319010 | N11: 2 | O11: 2 | P11: UN | Q11: PM | R11: 471 | S11: 942 | T11: 1 | U11: 2 | V11: 75 | W11: =SUMIFS($U$5:$U$44,$G$5:$G$44,G11) -> 43.25 | X11: =ROUND(V11*U11/W11,2) -> 3.47 | Y11: =IF(AND(U11=_xlfn.MAXIFS($U$5:$U$44,$G$5:$G$44,G11),COUNTIFS($G$5:G11,G11,$U$5:U11,U11)=1),1,0) -> 0 | Z11: =ROUND(IF(Y11=1,V11-(SUMIFS($X$5:$X$44,$G$5:$G$44,G11)-X11),X11),2) -> 3.47 | AA11: =IF(ABS(N11*R11-S11)<0.005,"OK","ОШИБКА") -> OK | AB11: =IF(ABS(O11*T11-U11)<0.0005,"OK","ОШИБКА") -> OK | AC11: =IF(H11=I11,"OK","ОШИБКА") -> OK | AD11: =IF(K11=L11,"OK","ОШИБКА") -> OK | AE11: =IF(N11=O11,"OK","ОШИБКА") -> OK
A12: 8 | B12: UZ95-041-2026 | C12: 5 / 6 | D12: 2 | E12: 1 | F12: 120x80x65 | G12: =B12&" | место "&E12 -> UZ95-041-2026 | место 1 | H12: Z10010403 | I12: Z10010403 | J12: TARJETA MVB(T) SICAS-T350 REPARADA | K12: ПЛАТА MVB(T) SICAS-T350 | L12: ПЛАТА MVB(T) SICAS-T350 | M12: 8542319010 | N12: 1 | O12: 1 | P12: UN | Q12: PM | R12: 185 | S12: 185 | T12: 0.2 | U12: 0.2 | V12: 75 | W12: =SUMIFS($U$5:$U$44,$G$5:$G$44,G12) -> 43.25 | X12: =ROUND(V12*U12/W12,2) -> 0.35 | Y12: =IF(AND(U12=_xlfn.MAXIFS($U$5:$U$44,$G$5:$G$44,G12),COUNTIFS($G$5:G12,G12,$U$5:U12,U12)=1),1,0) -> 0 | Z12: =ROUND(IF(Y12=1,V12-(SUMIFS($X$5:$X$44,$G$5:$G$44,G12)-X12),X12),2) -> 0.35 | AA12: =IF(ABS(N12*R12-S12)<0.005,"OK","ОШИБКА") -> OK | AB12: =IF(ABS(O12*T12-U12)<0.0005,"OK","ОШИБКА") -> OK | AC12: =IF(H12=I12,"OK","ОШИБКА") -> OK | AD12: =IF(K12=L12,"OK","ОШИБКА") -> OK | AE12: =IF(N12=O12,"OK","ОШИБКА") -> OK
A13: 9 | B13: UZ95-041-2026 | C13: 5 / 6 | D13: 2 | E13: 1 | F13: 120x80x65 | G13: =B13&" | место "&E13 -> UZ95-041-2026 | место 1 | H13: Z10010440 | I13: Z10010440 | J13: TARJETA ED1 SICAS-T350 REPARADO | K13: ПЛАТА ED1 SICAS-T350 | L13: ПЛАТА ED1 SICAS-T350 | M13: 8542319010 | N13: 1 | O13: 1 | P13: UN | Q13: PM | R13: 471 | S13: 471 | T13: 0.25 | U13: 0.25 | V13: 75 | W13: =SUMIFS($U$5:$U$44,$G$5:$G$44,G13) -> 43.25 | X13: =ROUND(V13*U13/W13,2) -> 0.43 | Y13: =IF(AND(U13=_xlfn.MAXIFS($U$5:$U$44,$G$5:$G$44,G13),COUNTIFS($G$5:G13,G13,$U$5:U13,U13)=1),1,0) -> 0 | Z13: =ROUND(IF(Y13=1,V13-(SUMIFS($X$5:$X$44,$G$5:$G$44,G13)-X13),X13),2) -> 0.43 | AA13: =IF(ABS(N13*R13-S13)<0.005,"OK","ОШИБКА") -> OK | AB13: =IF(ABS(O13*T13-U13)<0.0005,"OK","ОШИБКА") -> OK | AC13: =IF(H13=I13,"OK","ОШИБКА") -> OK | AD13: =IF(K13=L13,"OK","ОШИБКА") -> OK | AE13: =IF(N13=O13,"OK","ОШИБКА") -> OK
A14: 10 | B14: UZ95-041-2026 | C14: 5 / 6 | D14: 2 | E14: 1 | F14: 120x80x65 | G14: =B14&" | место "&E14 -> UZ95-041-2026 | место 1 | H14: Z5035563A | I14: Z5035563A | J14: DETECTOR DE HUMOS RECUPERADO | K14: ДАТЧИК ДЫМА | L14: ДАТЧИК ДЫМА | M14: 8531109500 | N14: 3 | O14: 3 | P14: UN | Q14: PM | R14: 240 | S14: 720 | T14: 0.4 | U14: 1.2 | V14: 75 | W14: =SUMIFS($U$5:$U$44,$G$5:$G$44,G14) -> 43.25 | X14: =ROUND(V14*U14/W14,2) -> 2.08 | Y14: =IF(AND(U14=_xlfn.MAXIFS($U$5:$U$44,$G$5:$G$44,G14),COUNTIFS($G$5:G14,G14,$U$5:U14,U14)=1),1,0) -> 0 | Z14: =ROUND(IF(Y14=1,V14-(SUMIFS($X$5:$X$44,$G$5:$G$44,G14)-X14),X14),2) -> 2.08 | AA14: =IF(ABS(N14*R14-S14)<0.005,"OK","ОШИБКА") -> OK | AB14: =IF(ABS(O14*T14-U14)<0.0005,"OK","ОШИБКА") -> OK | AC14: =IF(H14=I14,"OK","ОШИБКА") -> OK | AD14: =IF(K14=L14,"OK","ОШИБКА") -> OK | AE14: =IF(N14=O14,"OK","ОШИБКА") -> OK
A15: 11 | B15: UZ95-041-2026 | C15: 5 / 6 | D15: 2 | E15: 1 | F15: 120x80x65 | G15: =B15&" | место "&E15 -> UZ95-041-2026 | место 1 | H15: Z615677 | I15: Z615677 | J15: RACK ELECTRONICO ANTIBLOQUEO REPARADO | K15: БЛОК СИСТЕМЫ АБС | L15: БЛОК СИСТЕМЫ АБС | M15: 9032810000 | N15: 6 | O15: 6 | P15: UN | Q15: PM | R15: 312 | S15: 1872 | T15: 4.5 | U15: 27 | V15: 75 | W15: =SUMIFS($U$5:$U$44,$G$5:$G$44,G15) -> 43.25 | X15: =ROUND(V15*U15/W15,2) -> 46.82 | Y15: =IF(AND(U15=_xlfn.MAXIFS($U$5:$U$44,$G$5:$G$44,G15),COUNTIFS($G$5:G15,G15,$U$5:U15,U15)=1),1,0) -> 1 | Z15: =ROUND(IF(Y15=1,V15-(SUMIFS($X$5:$X$44,$G$5:$G$44,G15)-X15),X15),2) -> 46.82 | AA15: =IF(ABS(N15*R15-S15)<0.005,"OK","ОШИБКА") -> OK | AB15: =IF(ABS(O15*T15-U15)<0.0005,"OK","ОШИБКА") -> OK | AC15: =IF(H15=I15,"OK","ОШИБКА") -> OK | AD15: =IF(K15=L15,"OK","ОШИБКА") -> OK | AE15: =IF(N15=O15,"OK","ОШИБКА") -> OK
A16: 12 | B16: UZ95-042-2026 | C16: 7 / 8 | D16: 2 | E16: 0 | F16: 60x40x40 | G16: =B16&" | место "&E16 -> UZ95-042-2026 | место 0 | H16: Z10063008 | I16: Z10063008 | J16: INCLINOMETRO DIGITAL REPARADO | K16: ЦИФРОВОЙ ИНКЛИНОМЕТР | L16: ЦИФРОВОЙ ИНКЛИНОМЕТР | M16: 9015900000 | N16: 1 | O16: 1 | P16: UN | Q16: PM | R16: 350 | S16: 350 | T16: 0.5 | U16: 0.5 | V16: 10 | W16: =SUMIFS($U$5:$U$44,$G$5:$G$44,G16) -> 7.5 | X16: =ROUND(V16*U16/W16,2) -> 0.67 | Y16: =IF(AND(U16=_xlfn.MAXIFS($U$5:$U$44,$G$5:$G$44,G16),COUNTIFS($G$5:G16,G16,$U$5:U16,U16)=1),1,0) -> 0 | Z16: =ROUND(IF(Y16=1,V16-(SUMIFS($X$5:$X$44,$G$5:$G$44,G16)-X16),X16),2) -> 0.67 | AA16: =IF(ABS(N16*R16-S16)<0.005,"OK","ОШИБКА") -> OK | AB16: =IF(ABS(O16*T16-U16)<0.0005,"OK","ОШИБКА") -> OK | AC16: =IF(H16=I16,"OK","ОШИБКА") -> OK | AD16: =IF(K16=L16,"OK","ОШИБКА") -> OK | AE16: =IF(N16=O16,"OK","ОШИБКА") -> OK
... A44: 40 | B44: UZ95-045-2026 | C44: 13 / 14 | D44: 4 | E44: 1 | F44: 120x80x55 | G44: =B44&" | место "&E44 -> UZ95-045-2026 | место 1 | H44: Z5192559B | I44: Z5192559B | J44: VALVULA DE NIVEL,UZB F069 REPARADA | K44: УРОВНЕВЫЙ КЛАПАН, F069 | L44: УРОВНЕВЫЙ КЛАПАН, F069 | M44: 8481101908 | N44: 7 | O44: 7 | P44: UN | Q44: PM | R44: 138 | S44: 966 | T44: 2.5 | U44: 17.5 | V44: 460 | W44: =SUMIFS($U$5:$U$44,$G$5:$G$44,G44) -> 439.5 | X44: =ROUND(V44*U44/W44,2) -> 18.32 | Y44: =IF(AND(U44=_xlfn.MAXIFS($U$5:$U$44,$G$5:$G$44,G44),COUNTIFS($G$5:G44,G44,$U$5:U44,U44)=1),1,0) -> 0 | Z44: =ROUND(IF(Y44=1,V44-(SUMIFS($X$5:$X$44,$G$5:$G$44,G44)-X44),X44),2) -> 18.32 | AA44: =IF(ABS(N44*R44-S44)<0.005,"OK","ОШИБКА") -> OK | AB44: =IF(ABS(O44*T44-U44)<0.0005,"OK","ОШИБКА") -> OK | AC44: =IF(H44=I44,"OK","ОШИБКА") -> OK | AD44: =IF(K44=L44,"OK","ОШИБКА") -> OK | AE44: =IF(N44=O44,"OK","ОШИБКА") -> OK

Sheet Сверка
A1: Сверка итогов таблицы «Товары» с итогами, напечатанными в документах
A2: Синий шрифт — итоги из документов (строка TOTAL счёта / PL). Чёрный — формулы по листу «Товары».
A4: Счёт-проформа / PL № | B4: Строк в таблице | C4: Кол-во: итог счёта | D4: Кол-во: сумма строк | E4: Кол-во: итог PL | F4: Стоимость: TOTAL FACTURA, EUR | G4: Стоимость: сумма строк, EUR | H4: Расхождение стоимости, EUR | I4: Нетто: итог PL, кг | J4: Нетто: сумма строк, кг | K4: Расхождение нетто, кг | L4: Брутто: итог PL, кг | M4: Брутто: сумма строк, кг | N4: Расхождение брутто, кг | O4: Брутто > нетто | P4: Статус
A5: UZ95-039-2026 | B5: =COUNTIF(Товары!$B$5:$B$44,A5) -> 2 | C5: 2 | D5: =SUMIFS(Товары!$F$5:$F$44,Товары!$B$5:$B$44,A5) -> 2 | E5: 2 | F5: 3360 | G5: =SUMIFS(Товары!$H$5:$H$44,Товары!$B$5:$B$44,A5) -> 3360 | H5: =ROUND(G5-F5,2) -> 0 | I5: 9000 | J5: =SUMIFS(Товары!$J$5:$J$44,Товары!$B$5:$B$44,A5) -> 9000 | K5: =ROUND(J5-I5,2) -> 0 | L5: 9600 | M5: =SUMIFS(Товары!$I$5:$I$44,Товары!$B$5:$B$44,A5) -> 9600 | N5: =ROUND(M5-L5,2) -> 0 | O5: =IF(L5>I5,"OK","ОШИБКА") -> OK | P5: =IF(AND(C5=D5,D5=E5,H5=0,K5=0,N5=0,O5="OK"),"OK","РАСХОЖДЕНИЕ") -> OK
A6: UZ95-040-2026 | B6: =COUNTIF(Товары!$B$5:$B$44,A6) -> 3 | C6: 9 | D6: =SUMIFS(Товары!$F$5:$F$44,Товары!$B$5:$B$44,A6) -> 9 | E6: 9 | F6: 6840 | G6: =SUMIFS(Товары!$H$5:$H$44,Товары!$B$5:$B$44,A6) -> 6840 | H6: =ROUND(G6-F6,2) -> 0 | I6: 6165 | J6: =SUMIFS(Товары!$J$5:$J$44,Товары!$B$5:$B$44,A6) -> 6165 | K6: =ROUND(J6-I6,2) -> 0 | L6: 6915 | M6: =SUMIFS(Товары!$I$5:$I$44,Товары!$B$5:$B$44,A6) -> 6915 | N6: =ROUND(M6-L6,2) -> 0 | O6: =IF(L6>I6,"OK","ОШИБКА") -> OK | P6: =IF(AND(C6=D6,D6=E6,H6=0,K6=0,N6=0,O6="OK"),"OK","РАСХОЖДЕНИЕ") -> OK
A7: UZ95-041-2026 | B7: =COUNTIF(Товары!$B$5:$B$44,A7) -> 6 | C7: 20 | D7: =SUMIFS(Товары!$F$5:$F$44,Товары!$B$5:$B$44,A7) -> 20 | E7: 20 | F7: 4904 | G7: =SUMIFS(Товары!$H$5:$H$44,Товары!$B$5:$B$44,A7) -> 4904 | H7: =ROUND(G7-F7,2) -> 0 | I7: 43.25 | J7: =SUMIFS(Товары!$J$5:$J$44,Товары!$B$5:$B$44,A7) -> 43.25 | K7: =ROUND(J7-I7,2) -> 0 | L7: 75 | M7: =SUMIFS(Товары!$I$5:$I$44,Товары!$B$5:$B$44,A7) -> 75 | N7: =ROUND(M7-L7,2) -> 0 | O7: =IF(L7>I7,"OK","ОШИБКА") -> OK | P7: =IF(AND(C7=D7,D7=E7,H7=0,K7=0,N7=0,O7="OK"),"OK","РАСХОЖДЕНИЕ") -> OK
A8: UZ95-042-2026 | B8: =COUNTIF(Товары!$B$5:$B$44,A8) -> 3 | C8: 3 | D8: =SUMIFS(Товары!$F$5:$F$44,Товары!$B$5:$B$44,A8) -> 3 | E8: 3 | F8: 1990 | G8: =SUMIFS(Товары!$H$5:$H$44,Товары!$B$5:$B$44,A8) -> 1990 | H8: =ROUND(G8-F8,2) -> 0 | I8: 7.5 | J8: =SUMIFS(Товары!$J$5:$J$44,Товары!$B$5:$B$44,A8) -> 7.5 | K8: =ROUND(J8-I8,2) -> 0 | L8: 10 | M8: =SUMIFS(Товары!$I$5:$I$44,Товары!$B$5:$B$44,A8) -> 10 | N8: =ROUND(M8-L8,2) -> 0 | O8: =IF(L8>I8,"OK","ОШИБКА") -> OK | P8: =IF(AND(C8=D8,D8=E8,H8=0,K8=0,N8=0,O8="OK"),"OK","РАСХОЖДЕНИЕ") -> OK
A9: UZ95-043-2026 | B9: =COUNTIF(Товары!$B$5:$B$44,A9) -> 14 | C9: 22 | D9: =SUMIFS(Товары!$F$5:$F$44,Товары!$B$5:$B$44,A9) -> 22 | E9: 22 | F9: 13567.15 | G9: =SUMIFS(Товары!$H$5:$H$44,Товары!$B$5:$B$44,A9) -> 13715.71 | H9: =ROUND(G9-F9,2) -> 148.56 | I9: 191.7 | J9: =SUMIFS(Товары!$J$5:$J$44,Товары!$B$5:$B$44,A9) -> 191.7 | K9: =ROUND(J9-I9,2) -> 0 | L9: 235 | M9: =SUMIFS(Товары!$I$5:$I$44,Товары!$B$5:$B$44,A9) -> 235 | N9: =ROUND(M9-L9,2) -> 0 | O9: =IF(L9>I9,"OK","ОШИБКА") -> OK | P9: =IF(AND(C9=D9,D9=E9,H9=0,K9=0,N9=0,O9="OK"),"OK","РАСХОЖДЕНИЕ") -> РАСХОЖДЕНИЕ
A10: UZ95-044-2026 | B10: =COUNTIF(Товары!$B$5:$B$44,A10) -> 2 | C10: 29 | D10: =SUMIFS(Товары!$F$5:$F$44,Товары!$B$5:$B$44,A10) -> 29 | E10: 29 | F10: 1150 | G10: =SUMIFS(Товары!$H$5:$H$44,Товары!$B$5:$B$44,A10) -> 1150 | H10: =ROUND(G10-F10,2) -> 0 | I10: 348 | J10: =SUMIFS(Товары!$J$5:$J$44,Товары!$B$5:$B$44,A10) -> 348 | K10: =ROUND(J10-I10,2) -> 0 | L10: 370 | M10: =SUMIFS(Товары!$I$5:$I$44,Товары!$B$5:$B$44,A10) -> 370 | N10: =ROUND(M10-L10,2) -> 0 | O10: =IF(L10>I10,"OK","ОШИБКА") -> OK | P10: =IF(AND(C10=D10,D10=E10,H10=0,K10=0,N10=0,O10="OK"),"OK","РАСХОЖДЕНИЕ") -> OK
A11: UZ95-045-2026 | B11: =COUNTIF(Товары!$B$5:$B$44,A11) -> 10 | C11: 44 | D11: =SUMIFS(Товары!$F$5:$F$44,Товары!$B$5:$B$44,A11) -> 44 | E11: 44 | F11: 4320.54 | G11: =SUMIFS(Товары!$H$5:$H$44,Товары!$B$5:$B$44,A11) -> 4320.54 | H11: =ROUND(G11-F11,2) -> 0 | I11: 439.5 | J11: =SUMIFS(Товары!$J$5:$J$44,Товары!$B$5:$B$44,A11) -> 439.5 | K11: =ROUND(J11-I11,2) -> 0 | L11: 460 | M11: =SUMIFS(Товары!$I$5:$I$44,Товары!$B$5:$B$44,A11) -> 460 | N11: =ROUND(M11-L11,2) -> 0 | O11: =IF(L11>I11,"OK","ОШИБКА") -> OK | P11: =IF(AND(C11=D11,D11=E11,H11=0,K11=0,N11=0,O11="OK"),"OK","РАСХОЖДЕНИЕ") -> OK
A12: ИТОГО | B12: =SUM(B5:B11) -> 40 | C12: =SUM(C5:C11) -> 129 | D12: =SUM(D5:D11) -> 129 | E12: =SUM(E5:E11) -> 129 | F12: =SUM(F5:F11) -> 36131.69 | G12: =SUM(G5:G11) -> 36280.25 | H12: =ROUND(G12-F12,2) -> 148.56 | I12: =SUM(I5:I11) -> 16194.95 | J12: =SUM(J5:J11) -> 16194.95 | K12: =ROUND(J12-I12,2) -> 0 | L12: =SUM(L5:L11) -> 17665 | M12: =SUM(M5:M11) -> 17665 | N12: =ROUND(M12-L12,2) -> 0 | P12: =IF(COUNTIF(P5:P11,"OK")=7,"OK","РАСХОЖДЕНИЕ") -> РАСХОЖДЕНИЕ
A15: Построчные проверки (лист «Исходные данные»)
A16: Строк, где кол-во × цена ≠ стоимость | H16: =COUNTIF('Исходные данные'!AA5:AA44,"ОШИБКА") -> 0
A17: Строк, где кол-во × вес 1 шт. ≠ нетто | H17: =COUNTIF('Исходные данные'!AB5:AB44,"ОШИБКА") -> 0
A18: Строк, где артикул в счёте ≠ артикулу в PL | H18: =COUNTIF('Исходные данные'!AC5:AC44,"ОШИБКА") -> 0
A19: Строк, где наименование в счёте ≠ наименованию в PL | H19: =COUNTIF('Исходные данные'!AD5:AD44,"ОШИБКА") -> 0
A20: Строк, где кол-во в счёте ≠ кол-ву в PL | H20: =COUNTIF('Исходные данные'!AE5:AE44,"ОШИБКА") -> 0
A21: Строк, где код ТН ВЭД не 10-значный | H21: =SUMPRODUCT(--(LEN('Исходные данные'!M5:M44)<>10)) -> 0
A22: Строк, где стоимость, вес нетто или брутто ≤ 0 | H22: =COUNTIF(Товары!$H$5:$H$44,"<=0")+COUNTIF(Товары!$I$5:$I$44,"<=0")+COUNTIF(Товары!$J$5:$J$44,"<=0") -> 0

Sheet Замечания
A1: Замечания аудитора по комплекту документов
A2: Коды ТН ВЭД перенесены строго как в документах. Комментарии к классификации сделаны на уровне 6 знаков ГС по текстам товарных позиций/субпозиций; национальные знаки (7–10) не проверялись — нет доступа к актуальной редакции тарифа. Окончательное решение о классификации — за декларантом.
A4: № | B4: Уровень | C4: Документ | D4: Артикул(ы) | E4: Суть замечания | F4: Как отражено в таблице / рекомендация | G4: Уверенность
A5: 1 | B5: Критично | C5: UZ95-043-2026 | D5: Z5039543A | E5: TOTAL FACTURA = 13 567,15 EUR, а сумма 14 строк счёта = 13 715,71 EUR. Разница 148,56 EUR в точности равна стоимости последней строки (Z5039543A «ЦЕНТРАЛЬНАЯ ПАНЕЛЬ УПРАВЛЕНИЯ», 1 шт × 148,56). Итог по количеству (22 шт) эту строку включает, итог по стоимости — нет. Вероятно, диапазон суммирования в счёте не захватил последнюю строку. | F5: В таблицу перенесены построчные значения: итог таблицы 36 280,25 EUR против 36 131,69 EUR по сумме TOTAL FACTURA. До подачи декларации запросить у отправителя исправленный счёт или подтверждение верной суммы. | G5: Высокая — арифметика проверена
A6: 2 | B6: Требует проверки | C6: UZ95-044-2026, UZ95-045-2026 | D6: Z5050055A, Z5172926A, Z10010755 | E6: Однотипные амортизаторы отнесены к разным субпозициям: 8607 19 (части тележек, осей, колёс) и 8607 91 (прочие части локомотивов). Самый явный случай: «ПОПЕРЕЧНЫЙ АНТИВИБРАЦИОННЫЙ АМОРТИЗАТОР» Z5050055A → 8607919000, а Z5050054A, Z5050057A, Z5050058A с тем же наименованием → 8607199000. В счёте 044: «АМОРТИЗАТОР 130,730,102,112» → 8607919000, «АМОРТИЗАТОР 130» → 8607199000; в 045 «АМОРТИЗАТОР» Z5172926A → 8607919000. | F6: Коды перенесены как в документах. Разница может объясняться местом установки (тележка / кузов), но из документов это не следует — запросить обоснование. | G6: Высокая — в части факта расхождения; верный код не определяю
A7: 3 | B7: Требует проверки | C7: UZ95-043-2026 | D7: Z10035979 | E7: «КОНТАКТОР 100A 4000V» заявлен в 8536490000. Товарная позиция 8536 — аппаратура на напряжение не более 1000 В; свыше 1000 В — позиция 8535. | F7: Код перенесён как в документе. Если 4000 В — номинальное рабочее напряжение, код подлежит пересмотру. | G7: Средняя: текст позиций — уверен; что означает 4000V (рабочее или испытательное напряжение) — из документа неясно
A8: 4 | B8: Требует проверки | C8: UZ95-041-2026 | D8: Z615677 | E8: «БЛОК СИСТЕМЫ АБС» (исп. RACK ELECTRONICO ANTIBLOQUEO — электронная стойка) заявлен в 9032810000. Субпозиция 9032 81 — приборы гидравлические или пневматические; прочие (в т.ч. электронные) — 9032 89. | F8: Код перенесён как в документе; проверить по техническому описанию. | G8: Средняя
A9: 5 | B9: Требует проверки | C9: UZ95-041-2026, UZ95-043-2026 | D9: Z10001389, Z10010402, Z10010403, Z10010440, Z10001801, Z10030325, Z10037794, Z10062945 | E9: Модули и платы заявлены в 8542319010 (электронные интегральные схемы — процессоры и контроллеры). Собранные платы/модули, как правило, не являются интегральными схемами в смысле примечания к группе 85 и классифицируются иначе (например, как части оборудования). | F9: Коды перенесены как в документах; рекомендуется проверка классификации по техническому описанию. | G9: Средняя
A10: 6 | B10: Требует проверки | C10: UZ95-043-2026 | D10: Z10035917 | E10: «ПЛАТА ТЕМПЕРАТУРЫ (PT100)» (исп. MULTIPLEXOR DE TEMPERATURA) заявлена в 8531109500 — тот же код, что у «ДАТЧИК ДЫМА». Субпозиция 8531 10 — устройства охранной или пожарной сигнализации и аналогичная аппаратура; мультиплексор температуры к ним явно не относится. | F10: Код перенесён как в документе. | G10: Средняя
A11: 7 | B11: Требует проверки | C11: UZ95-042-2026 | D11: Z10063008, Z594470 | E11: Код 9015900000 — субпозиция 9015 90 «части и принадлежности». «ЦИФРОВОЙ ИНКЛИНОМЕТР» — законченный прибор, а не часть (возможно, 9015 80). Назначение Z594470 «КЛЕЩЕ (ПАТРОН) КАЛИБРОВОЧНЫЙ» (исп. PATRON — эталон/шаблон) из документов неясно. | F11: Коды перенесены как в документе. | G11: Средняя
A12: 8 | B12: Опечатка | C12: UZ95-043-2026 | D12: Z10014704 | E12: «ЭЛЕКТРОНУМАТИЧЕСКИЙ МОДУЛЯТОР (ЭПМ)» — пропущены буквы; по исп. ELECTRONEUMATICO и аббревиатуре ЭПМ правильно «ЭЛЕКТРОПНЕВМАТИЧЕСКИЙ». Опечатка одинаковая в счёте и PL. | F12: Перенесено как в оригинале; в декларации рекомендуется исправить. | G12: Высокая
A13: 9 | B13: Неясное наименование | C13: UZ95-042-2026 | D13: Z594470 | E13: «КЛЕЩЕ (ПАТРОН) КАЛИБРОВОЧНЫЙ» — «КЛЕЩЕ» не является корректной словоформой (возможно, имелось в виду «КЛЕЩИ»). Исп.: PATRON REPARADO/CALIBRADO — эталон (шаблон) отремонтированный/откалиброванный. | F13: Перенесено как в оригинале; уточнить у отправителя. | G13: Высокая — в части факта; что имелось в виду, я не знаю
A14: 10 | B14: Расчёт (не из документа) | C14: UZ95-041 … 045-2026 | D14: — | E14: В упаковочных листах 041–045 вес брутто указан на грузовое место целиком (объединённая ячейка), а не на каждую позицию. | F14: Вес брутто по позициям рассчитан пропорционально весу нетто (округление до 0,01 кг, остаток округления — на позицию с наибольшим нетто в месте); суммы по местам точно равны PL. Ячейки выделены жёлтым. Для 039 и 040 брутто указан по каждому месту = позиции и взят напрямую. | G14: Метод — расчётный; суммы проверены формулами
A15: 11 | B15: Уточнить | C15: UZ95-041-2026, UZ95-042-2026 | D15: — | E15: В обоих счетах указан № паллеты 2, но в PL это разные места: PL 041 — место 1, 120×80×65 см, брутто 75 кг; PL 042 — место «0», 60×40×40 см, брутто 10 кг. Номера паллет в счетах: 1, 2, 3, 4, 5, 6, 7, 10, 11 — №8 и №9 в комплекте отсутствуют. | F15: Уточнить фактическое количество грузовых мест и нет ли в этой отправке других счетов. | G15: Высокая — в части факта
A16: 12 | B16: Информация | C16: все | D16: Z10001389, Z10001801, Z10014712, Z10035917, Z10037362, Z10050907, Z5050055A, Z5050057A, Z5050058A | E16: Почти все позиции в исп. описании помечены REPARADO / REP / RECUPERADO (отремонтированные), но в русских наименованиях это не отражено. Без такой пометки в исп. описании — только перечисленные артикулы. | F16: Может иметь значение для выбора таможенной процедуры (вывоз/возврат после ремонта). | G16: Высокая — в части факта
A17: 13 | B17: Информация | C17: все | D17: — | E17: Во всех 7 счетах: «стоимость только для таможенных целей»; IVA 0 %; «включено 0,50 кг переработанной пластиковой упаковки (EPE)». Реквизиты отправителя, получателя и контактного лица во всех 14 документах совпадают. | F17: Справочно. | G17: Высокая
